Workbook

Sheet Read Me
B1: boAt vs Noise -- Amazon.in Sponsored-Ad / Keyword-Placement Audit
B3: What this dataset is
B4: A scrape of live Amazon.in search results for 16 keywords covering boAt and Noise TWS earbuds and wearables, captured via the Apify actor crawloop/amazon-search-scraper. Each row is one product card seen in the search-results grid for one keyword, tagged with whether Amazon marked it as a Sponsored (paid ad) placement.
B6: The 16 keywords break down as:
B7: - 6 exact-SKU searches: boAt Nirvana Ion ANC, boAt Chrome Horizon, boAt Lunar Vista, Noise Buds N2 Pro, Noise ColorFit Ultra 3, Noise Alt Watch 1
B8: - 6 category searches: wireless earbuds, earbuds with anc, bluetooth earbuds under 2000, smartwatch with bluetooth calling, smartwatch under 2000, smartwatch under 3000
B9: - 4 brand-defense / conquesting searches: boat earbuds, boat smartwatch, noise earbuds, noise smartwatch
B11: Column notes
B12: position -- the product's slot index within THAT PAGE's results grid for that keyword. IMPORTANT: position resets per page -- it is NOT a continuous rank across pages 1 and 2 (page 2's position 3 is not the 3rd item overall, it's the 3rd slot on page 2). Lower position = higher up / more visible on the page. Sponsored and organic items share the same position numbering, interleaved in the order they visually appear on the page, so a sponsored item at position 3 is far more prominent than one at position 20. You will see gaps in the sequence (e.g. jumping from 9 to 16, or page 1 not starting at 1) -- this is expected, not missing data: some grid slots are non-product SERP elements (banner ads, "customers also viewed" widgets, video tiles, brand carousels) that the scraper doesn't return as product rows.
B14: page -- which of the 2 search-results pages fetched per keyword (1 or 2) this row came from. Page 1 is far more valuable real estate than page 2: most shoppers never click through to page 2, so a sponsored slot on page 1 deserves much more weight in the analysis than the same position on page 2. This run captured 341 rows from page 1 and 325 from page 2.
B16: is_sponsored -- Yes/No, from Amazon's own "Sponsored" badge on that listing as detected by the scraper.
B18: brand -- boAt / Noise / "Other: <word>", auto-tagged by matching whole words in the title. "Other: X" means a competitor brand guessed from the first word of the title (e.g. "Other: Fire" = Fire-Boltt).
... B31: This data is from the actor crawloop/amazon-search-scraper. An earlier attempt used a different actor (scrapeify/amazon-scraper) which failed outright on 14 of 16 keywords (anti-bot "schema validation" errors) and, on the 2 keywords where it did return data, showed 0 sponsored placements across 47 results -- implausible for these search terms, and a sign its sponsored-ad detection wasn't reliable. crawloop's actor was verified against 3 test keywords (confirmed real, non-zero sponsored counts) before running the full 16-keyword sweep captured here.

Sheet Data
A1: keyword | B1: position | C1: page | D1: is_sponsored | E1: brand | F1: matched_sku | G1: asin | H1: title | I1: price | J1: product_url
A2: boAt Nirvana Ion ANC | B2: 3 | C2: 1 | D2: Yes | E2: Other: realme | G2: B0DBGP48NW | H2: realme | I2: ₹2,241 | J2: https://www.amazon.in/dp/B0DBGP48NW
A3: boAt Nirvana Ion ANC | B3: 4 | C3: 1 | D3: Yes | E3: boAt | G3: B0BW8TXJJ2 | H3: boAt | I3: ₹1,799 | J3: https://www.amazon.in/dp/B0BW8TXJJ2
A4: boAt Nirvana Ion ANC | B4: 5 | C4: 1 | D4: No | E4: boAt | G4: B0CF5QFH77 | H4: boAt | I4: ₹1,999 | J4: https://www.amazon.in/boAt-Nirvana-Ion-ANC-Cancellation/dp/B0CF5QFH77/ref=sr_1_3
A5: boAt Nirvana Ion ANC | B5: 6 | C5: 1 | D5: No | E5: boAt | G5: B0FP9DP8FH | H5: boAt | I5: ₹2,299 | J5: https://www.amazon.in/Nirvana-Battery-Bluetooth-Wireless-Earphones/dp/B0FP9DP8FH/ref=sr_1_4
A6: boAt Nirvana Ion ANC | B6: 7 | C6: 1 | D6: Yes | E6: Noise | G6: B0DS2Y94LS | H6: Noise | I6: ₹1,499 | J6: https://www.amazon.in/dp/B0DS2Y94LS
A7: boAt Nirvana Ion ANC | B7: 8 | C7: 1 | D7: Yes | E7: Noise | G7: B0D4QNLF6Y | H7: Noise | I7: ₹1,499 | J7: https://www.amazon.in/dp/B0D4QNLF6Y
A8: boAt Nirvana Ion ANC | B8: 12 | C8: 1 | D8: No | E8: Other: OnePlus | G8: B0FMDL81GS | H8: OnePlus | I8: ₹1,749 | J8: https://www.amazon.in/OnePlus-Playback-Translation-Dual-Device-Connectivity/dp/B0FMDL81GS/ref=sr_1_7
A9: boAt Nirvana Ion ANC | B9: 13 | C9: 1 | D9: No | E9: boAt | G9: B0DGTVLKPT | H9: boAt | I9: ₹1,899 | J9: https://www.amazon.in/boAt-Nirvana-Crystl-White-Lustre/dp/B0DGTVLKPT/ref=sr_1_8
A10: boAt Nirvana Ion ANC | B10: 14 | C10: 1 | D10: Yes | E10: Noise | G10: B0FN7J4997 | H10: Noise | I10: ₹1,599 | J10: https://www.amazon.in/dp/B0FN7J4997
A11: boAt Nirvana Ion ANC | B11: 15 | C11: 1 | D11: Yes | E11: Other: GOBOULT | G11: B0H6B1L8N1 | H11: GOBOULT | I11: ₹1,799 | J11: https://www.amazon.in/dp/B0H6B1L8N1
A12: boAt Nirvana Ion ANC | B12: 16 | C12: 1 | D12: No | E12: boAt | G12: B0DQKY3R84 | H12: boAt | I12: ₹1,999 | J12: https://www.amazon.in/boAt-Nirvana-TWS-Bluetooth-Earphones/dp/B0DQKY3R84/ref=sr_1_11
A13: boAt Nirvana Ion ANC | B13: 17 | C13: 1 | D13: No | E13: boAt | G13: B0D4VN3S8T | H13: boAt | I13: ₹2,299 | J13: https://www.amazon.in/boAt-Nirvana-Space-Multipoint-Connectivity/dp/B0D4VN3S8T/ref=sr_1_12
... A108: boAt Chrome Horizon | B108: 6 | C108: 2 | D108: No | E108: Other: GOBOULT | G108: B0G3PVS17V | H108: GOBOULT | I108: ₹2,999 | J108: https://www.amazon.in/GOBOULT-Saber-Functional-Watchfaces-Brightness/dp/B0G3PVS17V/ref=sr_1_20
A109: boAt Chrome Horizon | B109: 7 | C109: 2 | D109: No | E109: Other: CrossBeats | G109: B0F8GP4FL1 | H109: CrossBeats | J109: https://www.amazon.in/CrossBeats-Everest-Display-Bluetooth-Smartwatch/dp/B0F8GP4FL1/ref=sr_1_21
A110: boAt Chrome Horizon | B110: 8 | C110: 2 | D110: No | E110: boAt | F110: boAt Chrome Horizon | G110: B0GQQLW352 | H110: 2-Pack Screen Protector for Boat Chrome Horizon 1.51 inch Smartwatch – Flexible TPU Screen Guard, HD Clear, Anti Scratch, Bubble Free, Full Coverage Film – Not Tempered Glass | I110: ₹149 | J110: https://www.amazon.in/HELLOSCREEN-Boat-Chrome-Horizon-Smartwatch/dp/B0GQQLW352/ref=sr_1_22
A111: boAt Chrome Horizon | B111: 12 | C111: 2 | D111: No | E111: boAt | F111: boAt Chrome Horizon | G111: B0GTZY4H8T | H111: 2 Pack Smartwatch Screen Protector for Boat Chrome Horizon 1.51 inch – Flexible TPU Screen Guard, Ultra Thin, Scratch Resistant, Bubble Free, Full Coverage – Not Tempered Glass | I111: ₹149 | J111: https://www.amazon.in/PROTECTERR-Smartwatch-Protector-Chrome-Horizon/dp/B0GTZY4H8T/ref=sr_1_23
A112: boAt Chrome Horizon | B112: 13 | C112: 2 | D112: No | E112: boAt | F112: boAt Chrome Horizon | G112: B0FYFP7WLF | H112: Screen Protector Screenguard Compatible With BoAt Chrome Horizon (1.51 Inch), Edge to Edge Hydrogel TPU Screen Guard not a Tempered Glass (Pack of 3) | I112: ₹229 | J112: https://www.amazon.in/TELTREK-Screenguard-Compatible-Chrome-Horizon/dp/B0FYFP7WLF/ref=sr_1_24
A113: boAt Chrome Horizon | B113: 14 | C113: 2 | D113: No | E113: boAt | F113: boAt Chrome Horizon | G113: B0G35LCBM8 | H113: 3 Pack Screen Protector Compatible With BoAt Chrome Horizon (1.51 Inch) TPU Screen Guard Not a Tempered Glass | I113: ₹229 | J113: https://www.amazon.in/ZINGTEL-Compatible-BoAt-Chrome-Horizon/dp/B0G35LCBM8/ref=sr_1_25
A114: boAt Chrome Horizon | B114: 15 | C114: 2 | D114: No | E114: Other: Wisely | G114: B0FCY78Y66 | H114: Wisely | I114: ₹150 | J114: https://www.amazon.in/Wisely-Boat-Chrome-Horizon-Anti-Scratch/dp/B0FCY78Y66/ref=sr_1_26
A115: boAt Chrome Horizon | B115: 16 | C115: 2 | D115: No | E115: Other: AONES | G115: B0FBX6RRGH | H115: AONES | I115: ₹359 | J115: https://www.amazon.in/AONES-Leather-Silicone-Compatible-Smartwatch/dp/B0FBX6RRGH/ref=sr_1_27
A116: boAt Chrome Horizon | B116: 17 | C116: 2 | D116: No | E116: Other: AONES | G116: B0FC1R4J3Z | H116: AONES | I116: ₹449 | J116: https://www.amazon.in/AONES-Magnetic-Silicone-Compatible-Smartwatch/dp/B0FC1R4J3Z/ref=sr_1_28
A117: boAt Chrome Horizon | B117: 18 | C117: 2 | D117: No | E117: Other: AONES | G117: B0FC1P2H4N | H117: AONES | I117: ₹449 | J117: https://www.amazon.in/AONES-Magnetic-Silicone-Compatible-Smartwatch/dp/B0FC1P2H4N/ref=sr_1_29
A118: boAt Chrome Horizon | B118: 19 | C118: 2 | D118: No | E118: Other: AONES | G118: B0FC1P14N1 | H118: AONES | I118: ₹449 | J118: https://www.amazon.in/AONES-Magnetic-Silicone-Compatible-Smartwatch/dp/B0FC1P14N1/ref=sr_1_30
A119: boAt Chrome Horizon | B119: 23 | C119: 2 | D119: No | E119: Other: AONES | G119: B0FC1RTCYK | H119: AONES | I119: ₹449 | J119: https://www.amazon.in/AONES-Magnetic-Silicone-Compatible-Smartwatch/dp/B0FC1RTCYK/ref=sr_1_31
A120: boAt Chrome Horizon | B120: 24 | C120: 2 | D120: No | E120: Other: AONES | G120: B0FC1JJXQB | H120: AONES | I120: ₹429 | J120: https://www.amazon.in/AONES-Silicone-Compatible-Horizon-Smartwatch/dp/B0FC1JJXQB/ref=sr_1_32
A121: boAt Chrome Horizon | B121: 25 | C121: 2 | D121: No | E121: Other: AONES | G121: B0FD35ZGC4 | H121: AONES | I121: ₹469 | J121: https://www.amazon.in/AONES-Silicone-Magnetic-Compatible-Smartwatch/dp/B0FD35ZGC4/ref=sr_1_33
A122: boAt Chrome Horizon | B122: 26 | C122: 2 | D122: No | E122: Other: AONES | G122: B0FC1WRY8T | H122: AONES | I122: ₹429 | J122: https://www.amazon.in/AONES-Silicone-Compatible-Horizon-Smartwatch/dp/B0FC1WRY8T/ref=sr_1_34
A123: boAt Chrome Horizon | B123: 27 | C123: 2 | D123: No | E123: Other: YODI | G123: B0FRY2YHDD | H123: YODI | I123: ₹499 | J123: https://www.amazon.in/YODI-Parasuit-Compatible-Smartwatch-Accessories/dp/B0FRY2YHDD/ref=sr_1_35
A124: boAt Lunar Vista | B124: 2 | C124: 1 | D124: Yes | E124: boAt | G124: B0DFYL4635 | H124: boAt | I124: ₹1,599 | J124: https://www.amazon.in/dp/B0DFYL4635
A125: boAt Lunar Vista | B125: 3 | C125: 1 | D125: Yes | E125: Other: Fire | G125: B0F992RNJF | H125: Fire-Boltt | I125: ₹1,799 | J125: https://www.amazon.in/dp/B0F992RNJF
... A142: boAt Lunar Vista | B142: 25 | C142: 1 | D142: No | E142: Other: Fire | G142: B0BY2R74YW | H142: Fire-Boltt | I142: ₹1,499 | J142: https://www.amazon.in/Fire-Boltt-Bluetooth-Calling-Smartwatch-Assistance/dp/B0BY2R74YW/ref=sr_1_20
A143: boAt Lunar Vista | B143: 26 | C143: 1 | D143: No | E143: boAt | G143: B0GX9F6XY6 | H143: boAt | J143: https://www.amazon.in/boAt-Smartwatch-Charging-Functional-Tracking/dp/B0GX9F6XY6/ref=sr_1_21
A144: boAt Lunar Vista | B144: 27 | C144: 1 | D144: No | E144: boAt | G144: B0H5QGRDX8 | H144: boAt | I144: ₹1,499 | J144: https://www.amazon.in/boAt-Metallic-Tracking-Bluetooth-Emergency/dp/B0H5QGRDX8/ref=sr_1_22
A145: boAt Lunar Vista | B145: 3 | C145: 2 | D145: Yes | E145: Other: Fire | G145: B0B3RRWSF6 | H145: Fire-Boltt | I145: ₹1,299 | J145: https://www.amazon.in/dp/B0B3RRWSF6
A146: boAt Lunar Vista | B146: 4 | C146: 2 | D146: Yes | E146: Other: Fire | G146: B0CMF25TKG | H146: Fire‑Boltt Rise Smart Watch 1.85″ HD Display with Bluetooth Calling, AI Voice Assistant, Rotating Crown,SpO2 & Heart Rate Monitor, 120+ Sports Modes,IP67 Waterproof Smart Watch for Men & Women - Black | I146: ₹1,299 | J146: https://www.amazon.in/dp/B0CMF25TKG
A147: boAt Lunar Vista | B147: 5 | C147: 2 | D147: Yes | E147: Other: Nervfit | G147: B0DW9B76RV | H147: Nervfit | I147: ₹1,565 | J147: https://www.amazon.in/dp/B0DW9B76RV
A148: boAt Lunar Vista | B148: 6 | C148: 2 | D148: No | E148: boAt | G148: B0FBMGHL22 | H148: boAt | I148: ₹1,599 | J148: https://www.amazon.in/boAt-Infinity-Maximum-Capacity-Functional/dp/B0FBMGHL22/ref=sr_1_20
A149: boAt Lunar Vista | B149: 7 | C149: 2 | D149: No | E149: boAt | G149: B0CM38JVX4 | H149: boAt | I149: ₹3,499 | J149: https://www.amazon.in/boAt-Embrace-Functional-Metal-Built-Animated/dp/B0CM38JVX4/ref=sr_1_21
A150: boAt Lunar Vista | B150: 8 | C150: 2 | D150: No | E150: boAt | G150: B0GPDRBRBX | H150: boAt | I150: ₹1,699 | J150: https://www.amazon.in/boAt-Smartwatch-Immersive-Functional-Monitoring/dp/B0GPDRBRBX/ref=sr_1_22
...

Sheet Summary
A1: boAt vs Noise Amazon.in Ads Audit -- Summary
A3: Run totals
A4: Metric | B4: Value
A5: Total rows scraped | B5: =COUNTA(Data!A2:A667) -> 666
A6: Total sponsored slots | B6: =COUNTIF(Data!D2:D667,"Yes") -> 173
A7: Page 1 rows | B7: =COUNTIF(Data!C2:C667,1) -> 341
A8: Page 2 rows | B8: =COUNTIF(Data!C2:C667,2) -> 325
A9: Avg. sponsored position -- boAt | B9: =ROUND(AVERAGEIFS(Data!B2:B667,Data!D2:D667,"Yes",Data!E2:E667,"boAt"),1) -> 7
A10: Avg. sponsored position -- Noise | B10: =ROUND(AVERAGEIFS(Data!B2:B667,Data!D2:D667,"Yes",Data!E2:E667,"Noise"),1) -> 9
A12: Sponsored share-of-voice by brand (all 16 keywords combined)
A13: Brand | B13: Sponsored slots | C13: % of sponsored
A14: Noise | B14: =COUNTIFS(Data!D2:D667,"Yes",Data!E2:E667,"Noise") -> 93 | C14: =B14/$B$6 -> 0.53757225
A15: Other: Fire | B15: =COUNTIFS(Data!D2:D667,"Yes",Data!E2:E667,"Other: Fire") -> 28 | C15: =B15/$B$6 -> 0.16184971
A16: Other: Fastrack | B16: =COUNTIFS(Data!D2:D667,"Yes",Data!E2:E667,"Other: Fastrack") -> 15 | C16: =B16/$B$6 -> 0.086705202
A17: boAt | B17: =COUNTIFS(Data!D2:D667,"Yes",Data!E2:E667,"boAt") -> 10 | C17: =B17/$B$6 -> 0.057803468
A18: Other: Wireless | B18: =COUNTIFS(Data!D2:D667,"Yes",Data!E2:E667,"Other: Wireless") -> 5 | C18: =B18/$B$6 -> 0.028901734
A19: Other: realme | B19: =COUNTIFS(Data!D2:D667,"Yes",Data!E2:E667,"Other: realme") -> 3 | C19: =B19/$B$6 -> 0.01734104
A20: Other: GOBOULT | B20: =COUNTIFS(Data!D2:D667,"Yes",Data!E2:E667,"Other: GOBOULT") -> 3 | C20: =B20/$B$6 -> 0.01734104
A21: Other: Pebble | B21: =COUNTIFS(Data!D2:D667,"Yes",Data!E2:E667,"Other: Pebble") -> 3 | C21: =B21/$B$6 -> 0.01734104
A22: Other: Mivi | B22: =COUNTIFS(Data!D2:D667,"Yes",Data!E2:E667,"Other: Mivi") -> 2 | C22: =B22/$B$6 -> 0.011560694
A23: Other: PunnkFunnk | B23: =COUNTIFS(Data!D2:D667,"Yes",Data!E2:E667,"Other: PunnkFunnk") -> 2 | C23: =B23/$B$6 -> 0.011560694
A24: Other: Titan | B24: =COUNTIFS(Data!D2:D667,"Yes",Data!E2:E667,"Other: Titan") -> 2 | C24: =B24/$B$6 -> 0.011560694
A25: Other: truke | B25: =COUNTIFS(Data!D2:D667,"Yes",Data!E2:E667,"Other: truke") -> 1 | C25: =B25/$B$6 -> 0.0057803468
A26: Other: Apple | B26: =COUNTIFS(Data!D2:D667,"Yes",Data!E2:E667,"Other: Apple") -> 1 | C26: =B26/$B$6 -> 0.0057803468
A27: Other: Single | B27: =COUNTIFS(Data!D2:D667,"Yes",Data!E2:E667,"Other: Single") -> 1 | C27: =B27/$B$6 -> 0.0057803468
A28: Other: Ultrapods | B28: =COUNTIFS(Data!D2:D667,"Yes",Data!E2:E667,"Other: Ultrapods") -> 1 | C28: =B28/$B$6 -> 0.0057803468
A29: Other: Nervfit | B29: =COUNTIFS(Data!D2:D667,"Yes",Data!E2:E667,"Other: Nervfit") -> 1 | C29: =B29/$B$6 -> 0.0057803468
A30: Other: JLab | B30: =COUNTIFS(Data!D2:D667,"Yes",Data!E2:E667,"Other: JLab") -> 1 | C30: =B30/$B$6 -> 0.0057803468
A31: Other: MONKEYMAN | B31: =COUNTIFS(Data!D2:D667,"Yes",Data!E2:E667,"Other: MONKEYMAN") -> 1 | C31: =B31/$B$6 -> 0.0057803468
A33: SKU-level conquesting: competitor sponsored ads on each SKU's own name search
A34: ("conquesting" = a sponsored ad from a brand other than the SKU's own, on that exact SKU's name search)
A35: SKU search (keyword) | B35: Competitor brand | C35: Sponsored slots taken
A36: boAt Nirvana Ion ANC | B36: Noise | C36: =COUNTIFS(Data!A2:A667,"boAt Nirvana Ion ANC",Data!D2:D667,"Yes",Data!E2:E667,"Noise") -> 5
A37: boAt Nirvana Ion ANC | B37: Other: realme | C37: =COUNTIFS(Data!A2:A667,"boAt Nirvana Ion ANC",Data!D2:D667,"Yes",Data!E2:E667,"Other: realme") -> 1
A38: boAt Nirvana Ion ANC | B38: Other: GOBOULT | C38: =COUNTIFS(Data!A2:A667,"boAt Nirvana Ion ANC",Data!D2:D667,"Yes",Data!E2:E667,"Other: GOBOULT") -> 1
A39: boAt Nirvana Ion ANC | B39: Other: truke | C39: =COUNTIFS(Data!A2:A667,"boAt Nirvana Ion ANC",Data!D2:D667,"Yes",Data!E2:E667,"Other: truke") -> 1
A40: Noise Buds N2 Pro | B40: Other: Wireless | C40: =COUNTIFS(Data!A2:A667,"Noise Buds N2 Pro",Data!D2:D667,"Yes",Data!E2:E667,"Other: Wireless") -> 3
A41: Noise Buds N2 Pro | B41: Other: Apple | C41: =COUNTIFS(Data!A2:A667,"Noise Buds N2 Pro",Data!D2:D667,"Yes",Data!E2:E667,"Other: Apple") -> 1
A42: Noise Buds N2 Pro | B42: Other: Mivi | C42: =COUNTIFS(Data!A2:A667,"Noise Buds N2 Pro",Data!D2:D667,"Yes",Data!E2:E667,"Other: Mivi") -> 1
A43: Noise Buds N2 Pro | B43: Other: Single | C43: =COUNTIFS(Data!A2:A667,"Noise Buds N2 Pro",Data!D2:D667,"Yes",Data!E2:E667,"Other: Single") -> 1
...
